2022-03-01 17:07:21.586 | INFO     | main:create_app:28 - 日志初始化成功！！！
2022-03-01 17:07:26.102 | INFO     | register.middleware:intercept:19 - 访问记录:IP:127.0.0.1-method:GET-url:http://127.0.0.1:9000/api/dashboard
2022-03-01 17:07:28.143 | INFO     | utils.resp_code:resp_200:17 - token失效
2022-03-01 17:07:28.146 | ERROR    | register.exception:all_exception_handler:118 - 全局异常
GETURL:http://127.0.0.1:9000/api/dashboard
Headers:Headers({'host': '127.0.0.1:9000', 'connection': 'keep-alive', 'sec-ch-ua': '" Not A;Brand";v="99", "Chromium";v="98", "Microsoft Edge";v="98"', 'accept': 'application/json, text/plain, */*', 'authorization': 'eyJhbGciOiJIUzI1NiIsInR5cCI6IkpXVCJ9.eyJleHAiOjE2NDY3MzAwNjUsInN1YiI6IjEifQ.KmavDAg46e6ZCMoCoCvH_nAPWdXkQZW8Juqbyk3Xq58', 'sec-ch-ua-mobile': '?0', 'user-agent': 'Mozilla/5.0 (Windows NT 10.0; Win64; x64) AppleWebKit/537.36 (KHTML, like Gecko) Chrome/98.0.4758.102 Safari/537.36 Edg/98.0.1108.62', 'sec-ch-ua-platform': '"Windows"', 'origin': 'http://localhost:4000', 'sec-fetch-site': 'cross-site', 'sec-fetch-mode': 'cors', 'sec-fetch-dest': 'empty', 'referer': 'http://localhost:4000/', 'accept-encoding': 'gzip, deflate, br', 'accept-language': 'zh-CN,zh;q=0.9,en;q=0.8,en-GB;q=0.7,en-US;q=0.6'})
Traceback (most recent call last):
  File "D:\Program Files\Python\venu\backend1\lib\site-packages\starlette\middleware\errors.py", line 159, in __call__
    await self.app(scope, receive, _send)
  File "D:\Program Files\Python\venu\backend1\lib\site-packages\starlette\middleware\base.py", line 64, in __call__
    await response(scope, receive, send)
TypeError: 'dict' object is not callable

